WARNING:django.request:Bad Request: /api/v1/upload
INFO:django.utils.autoreload:C:\Users\rben\Desktop\Nzungu\backend\api\views.py changed, reloading.
INFO:botocore.credentials:Found credentials in environment variables.
INFO:root:3691cd7d-d910-415c-959f-6fd811e11e6f - 'file' key is not defined in the request
WARNING:django.request:Bad Request: /api/v1/upload
INFO:root:ebd8230d-714d-4ff8-9909-cdeea54d5f66 - Failed to upload file to s3 - 's3.ServiceResource' object has no attribute 'upload_fileobj'
INFO:django.utils.autoreload:C:\Users\rben\Desktop\Nzungu\backend\api\views.py changed, reloading.
INFO:botocore.credentials:Found credentials in environment variables.
INFO:django.utils.autoreload:C:\Users\rben\Desktop\Nzungu\backend\api\views.py changed, reloading.
INFO:botocore.credentials:Found credentials in environment variables.
INFO:django.utils.autoreload:C:\Users\rben\Desktop\Nzungu\backend\api\views.py changed, reloading.
INFO:botocore.credentials:Found credentials in environment variables.
INFO:django.utils.autoreload:C:\Users\rben\Desktop\Nzungu\backend\api\views.py changed, reloading.
INFO:botocore.credentials:Found credentials in environment variables.
INFO:django.utils.autoreload:C:\Users\rben\Desktop\Nzungu\backend\api\views.py changed, reloading.
INFO:botocore.credentials:Found credentials in environment variables.
INFO:django.utils.autoreload:C:\Users\rben\Desktop\Nzungu\backend\api\views.py changed, reloading.
INFO:botocore.credentials:Found credentials in environment variables.
INFO:django.utils.autoreload:C:\Users\rben\Desktop\Nzungu\backend\api\views.py changed, reloading.
INFO:botocore.credentials:Found credentials in environment variables.
INFO:botocore.credentials:Found credentials in environment variables.
WARNING:django.request:Bad Request: /api/v1/upload
ERROR:django.request:Internal Server Error: /api/v1/upload
Traceback (most recent call last):
  File "C:\Users\rben\AppData\Local\Programs\Python\Python310\lib\site-packages\django\core\handlers\exception.py", line 55, in inner
    response = get_response(request)
  File "C:\Users\rben\AppData\Local\Programs\Python\Python310\lib\site-packages\django\core\handlers\base.py", line 197, in _get_response
    response = wrapped_callback(request, *callback_args, **callback_kwargs)
  File "C:\Users\rben\AppData\Local\Programs\Python\Python310\lib\site-packages\django\views\decorators\csrf.py", line 65, in _view_wrapper
    return view_func(request, *args, **kwargs)
  File "C:\Users\rben\AppData\Local\Programs\Python\Python310\lib\site-packages\django\views\decorators\http.py", line 64, in inner
    return func(request, *args, **kwargs)
  File "C:\Users\rben\Desktop\Nzungu\backend\api\decorators.py", line 24, in inner
    item = dynamo_db.get_item(
  File "C:\Users\rben\AppData\Local\Programs\Python\Python310\lib\site-packages\botocore\client.py", line 601, in _api_call
    return self._make_api_call(operation_name, kwargs)
  File "C:\Users\rben\AppData\Local\Programs\Python\Python310\lib\site-packages\botocore\context.py", line 123, in wrapper
    return func(*args, **kwargs)
  File "C:\Users\rben\AppData\Local\Programs\Python\Python310\lib\site-packages\botocore\client.py", line 1031, in _make_api_call
    request_dict = self._convert_to_request_dict(
  File "C:\Users\rben\AppData\Local\Programs\Python\Python310\lib\site-packages\botocore\client.py", line 1098, in _convert_to_request_dict
    request_dict = self._serializer.serialize_to_request(
  File "C:\Users\rben\AppData\Local\Programs\Python\Python310\lib\site-packages\botocore\validate.py", line 381, in serialize_to_request
    raise ParamValidationError(report=report.generate_report())
botocore.exceptions.ParamValidationError: Parameter validation failed:
Invalid type for parameter Key.S, value: 1234, type: <class 'str'>, valid types: <class 'dict'>
ERROR:django.request:Internal Server Error: /api/v1/upload
Traceback (most recent call last):
  File "c:\Users\rben\AppData\Local\Programs\Python\Python310\lib\site-packages\django\core\handlers\exception.py", line 55, in inner
    response = get_response(request)
  File "c:\Users\rben\AppData\Local\Programs\Python\Python310\lib\site-packages\django\core\handlers\base.py", line 197, in _get_response
    response = wrapped_callback(request, *callback_args, **callback_kwargs)
  File "c:\Users\rben\AppData\Local\Programs\Python\Python310\lib\site-packages\django\views\decorators\csrf.py", line 65, in _view_wrapper
    return view_func(request, *args, **kwargs)
  File "c:\Users\rben\AppData\Local\Programs\Python\Python310\lib\site-packages\django\views\decorators\http.py", line 64, in inner
    return func(request, *args, **kwargs)
  File "C:\Users\rben\Desktop\Nzungu\backend\api\decorators.py", line 24, in inner
    item = dynamo_db.get_item(
  File "c:\Users\rben\AppData\Local\Programs\Python\Python310\lib\site-packages\botocore\client.py", line 601, in _api_call
    return self._make_api_call(operation_name, kwargs)
  File "c:\Users\rben\AppData\Local\Programs\Python\Python310\lib\site-packages\botocore\context.py", line 123, in wrapper
    return func(*args, **kwargs)
  File "c:\Users\rben\AppData\Local\Programs\Python\Python310\lib\site-packages\botocore\client.py", line 1031, in _make_api_call
    request_dict = self._convert_to_request_dict(
  File "c:\Users\rben\AppData\Local\Programs\Python\Python310\lib\site-packages\botocore\client.py", line 1098, in _convert_to_request_dict
    request_dict = self._serializer.serialize_to_request(
  File "c:\Users\rben\AppData\Local\Programs\Python\Python310\lib\site-packages\botocore\validate.py", line 381, in serialize_to_request
    raise ParamValidationError(report=report.generate_report())
botocore.exceptions.ParamValidationError: Parameter validation failed:
Invalid type for parameter Key.S, value: 1234, type: <class 'str'>, valid types: <class 'dict'>
ERROR:django.request:Internal Server Error: /api/v1/upload
Traceback (most recent call last):
  File "c:\Users\rben\AppData\Local\Programs\Python\Python310\lib\site-packages\django\core\handlers\exception.py", line 55, in inner
    response = get_response(request)
  File "c:\Users\rben\AppData\Local\Programs\Python\Python310\lib\site-packages\django\core\handlers\base.py", line 197, in _get_response
    response = wrapped_callback(request, *callback_args, **callback_kwargs)
  File "c:\Users\rben\AppData\Local\Programs\Python\Python310\lib\site-packages\django\views\decorators\csrf.py", line 65, in _view_wrapper
    return view_func(request, *args, **kwargs)
  File "c:\Users\rben\AppData\Local\Programs\Python\Python310\lib\site-packages\django\views\decorators\http.py", line 64, in inner
    return func(request, *args, **kwargs)
  File "C:\Users\rben\Desktop\Nzungu\backend\api\decorators.py", line 24, in inner
    item = dynamo_db.get_item(
  File "c:\Users\rben\AppData\Local\Programs\Python\Python310\lib\site-packages\botocore\client.py", line 601, in _api_call
    return self._make_api_call(operation_name, kwargs)
  File "c:\Users\rben\AppData\Local\Programs\Python\Python310\lib\site-packages\botocore\context.py", line 123, in wrapper
    return func(*args, **kwargs)
  File "c:\Users\rben\AppData\Local\Programs\Python\Python310\lib\site-packages\botocore\client.py", line 1031, in _make_api_call
    request_dict = self._convert_to_request_dict(
  File "c:\Users\rben\AppData\Local\Programs\Python\Python310\lib\site-packages\botocore\client.py", line 1098, in _convert_to_request_dict
    request_dict = self._serializer.serialize_to_request(
  File "c:\Users\rben\AppData\Local\Programs\Python\Python310\lib\site-packages\botocore\validate.py", line 381, in serialize_to_request
    raise ParamValidationError(report=report.generate_report())
botocore.exceptions.ParamValidationError: Parameter validation failed:
Invalid type for parameter Key.S, value: 1234, type: <class 'str'>, valid types: <class 'dict'>
INFO:django.utils.autoreload:C:\Users\rben\Desktop\Nzungu\backend\api\decorators.py changed, reloading.
ERROR:django.request:Internal Server Error: /api/v1/upload
Traceback (most recent call last):
  File "c:\Users\rben\AppData\Local\Programs\Python\Python310\lib\site-packages\django\core\handlers\exception.py", line 55, in inner
    response = get_response(request)
  File "c:\Users\rben\AppData\Local\Programs\Python\Python310\lib\site-packages\django\core\handlers\base.py", line 197, in _get_response
    response = wrapped_callback(request, *callback_args, **callback_kwargs)
  File "c:\Users\rben\AppData\Local\Programs\Python\Python310\lib\site-packages\django\views\decorators\csrf.py", line 65, in _view_wrapper
    return view_func(request, *args, **kwargs)
  File "c:\Users\rben\AppData\Local\Programs\Python\Python310\lib\site-packages\django\views\decorators\http.py", line 64, in inner
    return func(request, *args, **kwargs)
  File "C:\Users\rben\Desktop\Nzungu\backend\api\decorators.py", line 24, in inner
    item = dynamo_db.get_item(
  File "c:\Users\rben\AppData\Local\Programs\Python\Python310\lib\site-packages\botocore\client.py", line 601, in _api_call
    return self._make_api_call(operation_name, kwargs)
  File "c:\Users\rben\AppData\Local\Programs\Python\Python310\lib\site-packages\botocore\context.py", line 123, in wrapper
    return func(*args, **kwargs)
  File "c:\Users\rben\AppData\Local\Programs\Python\Python310\lib\site-packages\botocore\client.py", line 1031, in _make_api_call
    request_dict = self._convert_to_request_dict(
  File "c:\Users\rben\AppData\Local\Programs\Python\Python310\lib\site-packages\botocore\client.py", line 1098, in _convert_to_request_dict
    request_dict = self._serializer.serialize_to_request(
  File "c:\Users\rben\AppData\Local\Programs\Python\Python310\lib\site-packages\botocore\validate.py", line 381, in serialize_to_request
    raise ParamValidationError(report=report.generate_report())
botocore.exceptions.ParamValidationError: Parameter validation failed:
Missing required parameter in input: "Key"
Unknown parameter in input: "Item", must be one of: TableName, Key, AttributesToGet, ConsistentRead, ReturnConsumedCapacity, ProjectionExpression, ExpressionAttributeNames
INFO:django.utils.autoreload:C:\Users\rben\Desktop\Nzungu\backend\api\decorators.py changed, reloading.
ERROR:django.request:Internal Server Error: /api/v1/upload
Traceback (most recent call last):
  File "c:\Users\rben\AppData\Local\Programs\Python\Python310\lib\site-packages\django\core\handlers\exception.py", line 55, in inner
    response = get_response(request)
  File "c:\Users\rben\AppData\Local\Programs\Python\Python310\lib\site-packages\django\core\handlers\base.py", line 197, in _get_response
    response = wrapped_callback(request, *callback_args, **callback_kwargs)
  File "c:\Users\rben\AppData\Local\Programs\Python\Python310\lib\site-packages\django\views\decorators\csrf.py", line 65, in _view_wrapper
    return view_func(request, *args, **kwargs)
  File "c:\Users\rben\AppData\Local\Programs\Python\Python310\lib\site-packages\django\views\decorators\http.py", line 64, in inner
    return func(request, *args, **kwargs)
  File "C:\Users\rben\Desktop\Nzungu\backend\api\decorators.py", line 33, in inner
    print(item['Item'])
KeyError: 'Item'
INFO:django.utils.autoreload:C:\Users\rben\Desktop\Nzungu\backend\api\decorators.py changed, reloading.
WARNING:django.request:Forbidden: /api/v1/upload
INFO:django.utils.autoreload:C:\Users\rben\Desktop\Nzungu\backend\api\decorators.py changed, reloading.
WARNING:django.request:Not Found: /favicon.ico
INFO:django.utils.autoreload:C:\Users\rben\Desktop\Nzungu\backend\api\models.py changed, reloading.
INFO:django.utils.autoreload:C:\Users\rben\Desktop\Nzungu\backend\api\models.py changed, reloading.
INFO:django.utils.autoreload:C:\Users\rben\Desktop\Nzungu\backend\api\decorators.py changed, reloading.
WARNING:django.request:Forbidden: /api/v1/upload
ERROR:django.request:Internal Server Error: /api/v1/upload
ERROR:django.request:Internal Server Error: /api/v1/authenticate
Traceback (most recent call last):
  File "c:\Users\rben\AppData\Local\Programs\Python\Python310\lib\site-packages\django\core\handlers\exception.py", line 55, in inner
    response = get_response(request)
  File "c:\Users\rben\AppData\Local\Programs\Python\Python310\lib\site-packages\django\core\handlers\base.py", line 204, in _get_response
    self.check_response(response, callback)
  File "c:\Users\rben\AppData\Local\Programs\Python\Python310\lib\site-packages\django\core\handlers\base.py", line 332, in check_response
    raise ValueError(
ValueError: The view api.decorators.inner didn't return an HttpResponse object. It returned None instead.
INFO:django.utils.autoreload:C:\Users\rben\Desktop\Nzungu\backend\api\decorators.py changed, reloading.
ERROR:django.request:Internal Server Error: /api/v1/authenticate
Traceback (most recent call last):
  File "c:\Users\rben\AppData\Local\Programs\Python\Python310\lib\site-packages\django\core\handlers\exception.py", line 55, in inner
    response = get_response(request)
  File "c:\Users\rben\AppData\Local\Programs\Python\Python310\lib\site-packages\django\core\handlers\base.py", line 204, in _get_response
    self.check_response(response, callback)
  File "c:\Users\rben\AppData\Local\Programs\Python\Python310\lib\site-packages\django\core\handlers\base.py", line 332, in check_response
    raise ValueError(
ValueError: The view api.decorators.inner didn't return an HttpResponse object. It returned None instead.
WARNING:django.request:Bad Request: /api/v1/authenticate
INFO:django.utils.autoreload:C:\Users\rben\Desktop\Nzungu\backend\api\decorators.py changed, reloading.
WARNING:django.request:Bad Request: /api/v1/authenticate
ERROR:django.request:Internal Server Error: /api/v1/authenticate
Traceback (most recent call last):
  File "c:\Users\rben\AppData\Local\Programs\Python\Python310\lib\site-packages\django\core\handlers\exception.py", line 55, in inner
    response = get_response(request)
  File "c:\Users\rben\AppData\Local\Programs\Python\Python310\lib\site-packages\django\core\handlers\base.py", line 204, in _get_response
    self.check_response(response, callback)
  File "c:\Users\rben\AppData\Local\Programs\Python\Python310\lib\site-packages\django\core\handlers\base.py", line 332, in check_response
    raise ValueError(
ValueError: The view api.decorators.inner didn't return an HttpResponse object. It returned None instead.
INFO:django.utils.autoreload:C:\Users\rben\Desktop\Nzungu\backend\api\decorators.py changed, reloading.
INFO:django.utils.autoreload:C:\Users\rben\Desktop\Nzungu\backend\api\views.py changed, reloading.
INFO:django.utils.autoreload:C:\Users\rben\Desktop\Nzungu\backend\api\models.py changed, reloading.
INFO:django.utils.autoreload:C:\Users\rben\Desktop\Nzungu\backend\api\models.py changed, reloading.
INFO:django.utils.autoreload:C:\Users\rben\Desktop\Nzungu\backend\api\views.py changed, reloading.
INFO:django.utils.autoreload:C:\Users\rben\Desktop\Nzungu\backend\api\views.py changed, reloading.
ERROR:root:6514f3c8-ce69-4ce6-9ae9-963c862234ba - Failed to write authorization token to dynamodb - put_item() only accepts keyword arguments.
ERROR:django.request:Unknown Status Code: /api/v1/authenticate
INFO:django.utils.autoreload:C:\Users\rben\Desktop\Nzungu\backend\api\views.py changed, reloading.
ERROR:root:6b90d5e8-3da6-40be-9727-d0d41a74a236 - Failed to write authorization token to dynamodb - put_item() only accepts keyword arguments.
ERROR:django.request:Unknown Status Code: /api/v1/authenticate
INFO:django.utils.autoreload:C:\Users\rben\Desktop\Nzungu\backend\api\views.py changed, reloading.
ERROR:root:758f3c9e-34ad-4c4b-bd5a-34b5f6787b8b - Failed to write authorization token to dynamodb - put_item() only accepts keyword arguments.
ERROR:django.request:Unknown Status Code: /api/v1/authenticate
INFO:django.utils.autoreload:C:\Users\rben\Desktop\Nzungu\backend\api\views.py changed, reloading.
INFO:django.utils.autoreload:C:\Users\rben\Desktop\Nzungu\backend\api\decorators.py changed, reloading.
WARNING:django.request:Unauthorized: /api/v1/authenticate
INFO:django.utils.autoreload:C:\Users\rben\Desktop\Nzungu\backend\api\decorators.py changed, reloading.
WARNING:django.request:Forbidden: /api/v1/upload
INFO:django.utils.autoreload:C:\Users\rben\Desktop\Nzungu\backend\api\views.py changed, reloading.
WARNING:django.request:Forbidden: /api/v1/authenticate
WARNING:django.request:Unauthorized: /api/v1/upload
WARNING:django.request:Forbidden: /api/v1/authenticate
