WARNING:django.request:Bad Request: /api/v1/upload
INFO:django.utils.autoreload:C:\Users\rben\Desktop\Nzungu\backend\api\views.py changed, reloading.
INFO:botocore.credentials:Found credentials in environment variables.
INFO:root:3691cd7d-d910-415c-959f-6fd811e11e6f - 'file' key is not defined in the request
WARNING:django.request:Bad Request: /api/v1/upload
INFO:root:ebd8230d-714d-4ff8-9909-cdeea54d5f66 - Failed to upload file to s3 - 's3.ServiceResource' object has no attribute 'upload_fileobj'
INFO:django.utils.autoreload:C:\Users\rben\Desktop\Nzungu\backend\api\views.py changed, reloading.
INFO:botocore.credentials:Found credentials in environment variables.
INFO:django.utils.autoreload:C:\Users\rben\Desktop\Nzungu\backend\api\views.py changed, reloading.
INFO:botocore.credentials:Found credentials in environment variables.
INFO:django.utils.autoreload:C:\Users\rben\Desktop\Nzungu\backend\api\views.py changed, reloading.
INFO:botocore.credentials:Found credentials in environment variables.
INFO:django.utils.autoreload:C:\Users\rben\Desktop\Nzungu\backend\api\views.py changed, reloading.
INFO:botocore.credentials:Found credentials in environment variables.
INFO:django.utils.autoreload:C:\Users\rben\Desktop\Nzungu\backend\api\views.py changed, reloading.
INFO:botocore.credentials:Found credentials in environment variables.
INFO:django.utils.autoreload:C:\Users\rben\Desktop\Nzungu\backend\api\views.py changed, reloading.
INFO:botocore.credentials:Found credentials in environment variables.
INFO:django.utils.autoreload:C:\Users\rben\Desktop\Nzungu\backend\api\views.py changed, reloading.
INFO:botocore.credentials:Found credentials in environment variables.
INFO:botocore.credentials:Found credentials in environment variables.
WARNING:django.request:Bad Request: /api/v1/upload
ERROR:django.request:Internal Server Error: /api/v1/upload
Traceback (most recent call last):
  File "C:\Users\rben\AppData\Local\Programs\Python\Python310\lib\site-packages\django\core\handlers\exception.py", line 55, in inner
    response = get_response(request)
  File "C:\Users\rben\AppData\Local\Programs\Python\Python310\lib\site-packages\django\core\handlers\base.py", line 197, in _get_response
    response = wrapped_callback(request, *callback_args, **callback_kwargs)
  File "C:\Users\rben\AppData\Local\Programs\Python\Python310\lib\site-packages\django\views\decorators\csrf.py", line 65, in _view_wrapper
    return view_func(request, *args, **kwargs)
  File "C:\Users\rben\AppData\Local\Programs\Python\Python310\lib\site-packages\django\views\decorators\http.py", line 64, in inner
    return func(request, *args, **kwargs)
  File "C:\Users\rben\Desktop\Nzungu\backend\api\decorators.py", line 24, in inner
    item = dynamo_db.get_item(
  File "C:\Users\rben\AppData\Local\Programs\Python\Python310\lib\site-packages\botocore\client.py", line 601, in _api_call
    return self._make_api_call(operation_name, kwargs)
  File "C:\Users\rben\AppData\Local\Programs\Python\Python310\lib\site-packages\botocore\context.py", line 123, in wrapper
    return func(*args, **kwargs)
  File "C:\Users\rben\AppData\Local\Programs\Python\Python310\lib\site-packages\botocore\client.py", line 1031, in _make_api_call
    request_dict = self._convert_to_request_dict(
  File "C:\Users\rben\AppData\Local\Programs\Python\Python310\lib\site-packages\botocore\client.py", line 1098, in _convert_to_request_dict
    request_dict = self._serializer.serialize_to_request(
  File "C:\Users\rben\AppData\Local\Programs\Python\Python310\lib\site-packages\botocore\validate.py", line 381, in serialize_to_request
    raise ParamValidationError(report=report.generate_report())
botocore.exceptions.ParamValidationError: Parameter validation failed:
Invalid type for parameter Key.S, value: 1234, type: <class 'str'>, valid types: <class 'dict'>
ERROR:django.request:Internal Server Error: /api/v1/upload
Traceback (most recent call last):
  File "c:\Users\rben\AppData\Local\Programs\Python\Python310\lib\site-packages\django\core\handlers\exception.py", line 55, in inner
    response = get_response(request)
  File "c:\Users\rben\AppData\Local\Programs\Python\Python310\lib\site-packages\django\core\handlers\base.py", line 197, in _get_response
    response = wrapped_callback(request, *callback_args, **callback_kwargs)
  File "c:\Users\rben\AppData\Local\Programs\Python\Python310\lib\site-packages\django\views\decorators\csrf.py", line 65, in _view_wrapper
    return view_func(request, *args, **kwargs)
  File "c:\Users\rben\AppData\Local\Programs\Python\Python310\lib\site-packages\django\views\decorators\http.py", line 64, in inner
    return func(request, *args, **kwargs)
  File "C:\Users\rben\Desktop\Nzungu\backend\api\decorators.py", line 24, in inner
    item = dynamo_db.get_item(
  File "c:\Users\rben\AppData\Local\Programs\Python\Python310\lib\site-packages\botocore\client.py", line 601, in _api_call
    return self._make_api_call(operation_name, kwargs)
  File "c:\Users\rben\AppData\Local\Programs\Python\Python310\lib\site-packages\botocore\context.py", line 123, in wrapper
    return func(*args, **kwargs)
  File "c:\Users\rben\AppData\Local\Programs\Python\Python310\lib\site-packages\botocore\client.py", line 1031, in _make_api_call
    request_dict = self._convert_to_request_dict(
  File "c:\Users\rben\AppData\Local\Programs\Python\Python310\lib\site-packages\botocore\client.py", line 1098, in _convert_to_request_dict
    request_dict = self._serializer.serialize_to_request(
  File "c:\Users\rben\AppData\Local\Programs\Python\Python310\lib\site-packages\botocore\validate.py", line 381, in serialize_to_request
    raise ParamValidationError(report=report.generate_report())
botocore.exceptions.ParamValidationError: Parameter validation failed:
Invalid type for parameter Key.S, value: 1234, type: <class 'str'>, valid types: <class 'dict'>
ERROR:django.request:Internal Server Error: /api/v1/upload
Traceback (most recent call last):
  File "c:\Users\rben\AppData\Local\Programs\Python\Python310\lib\site-packages\django\core\handlers\exception.py", line 55, in inner
    response = get_response(request)
  File "c:\Users\rben\AppData\Local\Programs\Python\Python310\lib\site-packages\django\core\handlers\base.py", line 197, in _get_response
    response = wrapped_callback(request, *callback_args, **callback_kwargs)
  File "c:\Users\rben\AppData\Local\Programs\Python\Python310\lib\site-packages\django\views\decorators\csrf.py", line 65, in _view_wrapper
    return view_func(request, *args, **kwargs)
  File "c:\Users\rben\AppData\Local\Programs\Python\Python310\lib\site-packages\django\views\decorators\http.py", line 64, in inner
    return func(request, *args, **kwargs)
  File "C:\Users\rben\Desktop\Nzungu\backend\api\decorators.py", line 24, in inner
    item = dynamo_db.get_item(
  File "c:\Users\rben\AppData\Local\Programs\Python\Python310\lib\site-packages\botocore\client.py", line 601, in _api_call
    return self._make_api_call(operation_name, kwargs)
  File "c:\Users\rben\AppData\Local\Programs\Python\Python310\lib\site-packages\botocore\context.py", line 123, in wrapper
    return func(*args, **kwargs)
  File "c:\Users\rben\AppData\Local\Programs\Python\Python310\lib\site-packages\botocore\client.py", line 1031, in _make_api_call
    request_dict = self._convert_to_request_dict(
  File "c:\Users\rben\AppData\Local\Programs\Python\Python310\lib\site-packages\botocore\client.py", line 1098, in _convert_to_request_dict
    request_dict = self._serializer.serialize_to_request(
  File "c:\Users\rben\AppData\Local\Programs\Python\Python310\lib\site-packages\botocore\validate.py", line 381, in serialize_to_request
    raise ParamValidationError(report=report.generate_report())
botocore.exceptions.ParamValidationError: Parameter validation failed:
Invalid type for parameter Key.S, value: 1234, type: <class 'str'>, valid types: <class 'dict'>
INFO:django.utils.autoreload:C:\Users\rben\Desktop\Nzungu\backend\api\decorators.py changed, reloading.
ERROR:django.request:Internal Server Error: /api/v1/upload
Traceback (most recent call last):
  File "c:\Users\rben\AppData\Local\Programs\Python\Python310\lib\site-packages\django\core\handlers\exception.py", line 55, in inner
    response = get_response(request)
  File "c:\Users\rben\AppData\Local\Programs\Python\Python310\lib\site-packages\django\core\handlers\base.py", line 197, in _get_response
    response = wrapped_callback(request, *callback_args, **callback_kwargs)
  File "c:\Users\rben\AppData\Local\Programs\Python\Python310\lib\site-packages\django\views\decorators\csrf.py", line 65, in _view_wrapper
    return view_func(request, *args, **kwargs)
  File "c:\Users\rben\AppData\Local\Programs\Python\Python310\lib\site-packages\django\views\decorators\http.py", line 64, in inner
    return func(request, *args, **kwargs)
  File "C:\Users\rben\Desktop\Nzungu\backend\api\decorators.py", line 24, in inner
    item = dynamo_db.get_item(
  File "c:\Users\rben\AppData\Local\Programs\Python\Python310\lib\site-packages\botocore\client.py", line 601, in _api_call
    return self._make_api_call(operation_name, kwargs)
  File "c:\Users\rben\AppData\Local\Programs\Python\Python310\lib\site-packages\botocore\context.py", line 123, in wrapper
    return func(*args, **kwargs)
  File "c:\Users\rben\AppData\Local\Programs\Python\Python310\lib\site-packages\botocore\client.py", line 1031, in _make_api_call
    request_dict = self._convert_to_request_dict(
  File "c:\Users\rben\AppData\Local\Programs\Python\Python310\lib\site-packages\botocore\client.py", line 1098, in _convert_to_request_dict
    request_dict = self._serializer.serialize_to_request(
  File "c:\Users\rben\AppData\Local\Programs\Python\Python310\lib\site-packages\botocore\validate.py", line 381, in serialize_to_request
    raise ParamValidationError(report=report.generate_report())
botocore.exceptions.ParamValidationError: Parameter validation failed:
Missing required parameter in input: "Key"
Unknown parameter in input: "Item", must be one of: TableName, Key, AttributesToGet, ConsistentRead, ReturnConsumedCapacity, ProjectionExpression, ExpressionAttributeNames
INFO:django.utils.autoreload:C:\Users\rben\Desktop\Nzungu\backend\api\decorators.py changed, reloading.
ERROR:django.request:Internal Server Error: /api/v1/upload
Traceback (most recent call last):
  File "c:\Users\rben\AppData\Local\Programs\Python\Python310\lib\site-packages\django\core\handlers\exception.py", line 55, in inner
    response = get_response(request)
  File "c:\Users\rben\AppData\Local\Programs\Python\Python310\lib\site-packages\django\core\handlers\base.py", line 197, in _get_response
    response = wrapped_callback(request, *callback_args, **callback_kwargs)
  File "c:\Users\rben\AppData\Local\Programs\Python\Python310\lib\site-packages\django\views\decorators\csrf.py", line 65, in _view_wrapper
    return view_func(request, *args, **kwargs)
  File "c:\Users\rben\AppData\Local\Programs\Python\Python310\lib\site-packages\django\views\decorators\http.py", line 64, in inner
    return func(request, *args, **kwargs)
  File "C:\Users\rben\Desktop\Nzungu\backend\api\decorators.py", line 33, in inner
    print(item['Item'])
KeyError: 'Item'
INFO:django.utils.autoreload:C:\Users\rben\Desktop\Nzungu\backend\api\decorators.py changed, reloading.
WARNING:django.request:Forbidden: /api/v1/upload
INFO:django.utils.autoreload:C:\Users\rben\Desktop\Nzungu\backend\api\decorators.py changed, reloading.
WARNING:django.request:Not Found: /favicon.ico
INFO:django.utils.autoreload:C:\Users\rben\Desktop\Nzungu\backend\api\models.py changed, reloading.
INFO:django.utils.autoreload:C:\Users\rben\Desktop\Nzungu\backend\api\models.py changed, reloading.
INFO:django.utils.autoreload:C:\Users\rben\Desktop\Nzungu\backend\api\decorators.py changed, reloading.
WARNING:django.request:Forbidden: /api/v1/upload
ERROR:django.request:Internal Server Error: /api/v1/upload
ERROR:django.request:Internal Server Error: /api/v1/authenticate
Traceback (most recent call last):
  File "c:\Users\rben\AppData\Local\Programs\Python\Python310\lib\site-packages\django\core\handlers\exception.py", line 55, in inner
    response = get_response(request)
  File "c:\Users\rben\AppData\Local\Programs\Python\Python310\lib\site-packages\django\core\handlers\base.py", line 204, in _get_response
    self.check_response(response, callback)
  File "c:\Users\rben\AppData\Local\Programs\Python\Python310\lib\site-packages\django\core\handlers\base.py", line 332, in check_response
    raise ValueError(
ValueError: The view api.decorators.inner didn't return an HttpResponse object. It returned None instead.
INFO:django.utils.autoreload:C:\Users\rben\Desktop\Nzungu\backend\api\decorators.py changed, reloading.
ERROR:django.request:Internal Server Error: /api/v1/authenticate
Traceback (most recent call last):
  File "c:\Users\rben\AppData\Local\Programs\Python\Python310\lib\site-packages\django\core\handlers\exception.py", line 55, in inner
    response = get_response(request)
  File "c:\Users\rben\AppData\Local\Programs\Python\Python310\lib\site-packages\django\core\handlers\base.py", line 204, in _get_response
    self.check_response(response, callback)
  File "c:\Users\rben\AppData\Local\Programs\Python\Python310\lib\site-packages\django\core\handlers\base.py", line 332, in check_response
    raise ValueError(
ValueError: The view api.decorators.inner didn't return an HttpResponse object. It returned None instead.
WARNING:django.request:Bad Request: /api/v1/authenticate
INFO:django.utils.autoreload:C:\Users\rben\Desktop\Nzungu\backend\api\decorators.py changed, reloading.
WARNING:django.request:Bad Request: /api/v1/authenticate
ERROR:django.request:Internal Server Error: /api/v1/authenticate
Traceback (most recent call last):
  File "c:\Users\rben\AppData\Local\Programs\Python\Python310\lib\site-packages\django\core\handlers\exception.py", line 55, in inner
    response = get_response(request)
  File "c:\Users\rben\AppData\Local\Programs\Python\Python310\lib\site-packages\django\core\handlers\base.py", line 204, in _get_response
    self.check_response(response, callback)
  File "c:\Users\rben\AppData\Local\Programs\Python\Python310\lib\site-packages\django\core\handlers\base.py", line 332, in check_response
    raise ValueError(
ValueError: The view api.decorators.inner didn't return an HttpResponse object. It returned None instead.
INFO:django.utils.autoreload:C:\Users\rben\Desktop\Nzungu\backend\api\decorators.py changed, reloading.
INFO:django.utils.autoreload:C:\Users\rben\Desktop\Nzungu\backend\api\views.py changed, reloading.
INFO:django.utils.autoreload:C:\Users\rben\Desktop\Nzungu\backend\api\models.py changed, reloading.
INFO:django.utils.autoreload:C:\Users\rben\Desktop\Nzungu\backend\api\models.py changed, reloading.
INFO:django.utils.autoreload:C:\Users\rben\Desktop\Nzungu\backend\api\views.py changed, reloading.
INFO:django.utils.autoreload:C:\Users\rben\Desktop\Nzungu\backend\api\views.py changed, reloading.
ERROR:root:6514f3c8-ce69-4ce6-9ae9-963c862234ba - Failed to write authorization token to dynamodb - put_item() only accepts keyword arguments.
ERROR:django.request:Unknown Status Code: /api/v1/authenticate
INFO:django.utils.autoreload:C:\Users\rben\Desktop\Nzungu\backend\api\views.py changed, reloading.
ERROR:root:6b90d5e8-3da6-40be-9727-d0d41a74a236 - Failed to write authorization token to dynamodb - put_item() only accepts keyword arguments.
ERROR:django.request:Unknown Status Code: /api/v1/authenticate
INFO:django.utils.autoreload:C:\Users\rben\Desktop\Nzungu\backend\api\views.py changed, reloading.
ERROR:root:758f3c9e-34ad-4c4b-bd5a-34b5f6787b8b - Failed to write authorization token to dynamodb - put_item() only accepts keyword arguments.
ERROR:django.request:Unknown Status Code: /api/v1/authenticate
INFO:django.utils.autoreload:C:\Users\rben\Desktop\Nzungu\backend\api\views.py changed, reloading.
INFO:django.utils.autoreload:C:\Users\rben\Desktop\Nzungu\backend\api\decorators.py changed, reloading.
WARNING:django.request:Unauthorized: /api/v1/authenticate
INFO:django.utils.autoreload:C:\Users\rben\Desktop\Nzungu\backend\api\decorators.py changed, reloading.
WARNING:django.request:Forbidden: /api/v1/upload
INFO:django.utils.autoreload:C:\Users\rben\Desktop\Nzungu\backend\api\views.py changed, reloading.
WARNING:django.request:Forbidden: /api/v1/authenticate
WARNING:django.request:Unauthorized: /api/v1/upload
WARNING:django.request:Forbidden: /api/v1/authenticate
WARNING:django.request:Forbidden: /api/v1/upload
WARNING:django.request:Not Found: /favicon.ico
INFO:django.utils.autoreload:C:\Users\rben\Desktop\Nzungu\backend\api\admin.py changed, reloading.
INFO:django.utils.autoreload:C:\Users\rben\Desktop\Nzungu\backend\api\models.py changed, reloading.
WARNING:django.request:Not Found: /admin/api/upload/
INFO:django.utils.autoreload:C:\Users\rben\Desktop\Nzungu\backend\shared_models\models.py changed, reloading.
INFO:django.utils.autoreload:C:\Users\rben\Desktop\Nzungu\backend\shared_models\models.py changed, reloading.
INFO:django.utils.autoreload:C:\Users\rben\Desktop\Nzungu\backend\api\views.py changed, reloading.
INFO:django.utils.autoreload:C:\Users\rben\Desktop\Nzungu\backend\shared_models\models.py changed, reloading.
INFO:django.utils.autoreload:C:\Users\rben\Desktop\Nzungu\backend\shared_models\models.py changed, reloading.
INFO:django.utils.autoreload:C:\Users\rben\Desktop\Nzungu\backend\api\views.py changed, reloading.
INFO:django.utils.autoreload:C:\Users\rben\Desktop\Nzungu\backend\api\urls.py changed, reloading.
WARNING:django.request:Bad Request: /api/v1/get-products
ERROR:django.request:Internal Server Error: /api/v1/get-products
Traceback (most recent call last):
  File "C:\Users\rben\AppData\Local\Programs\Python\Python310\lib\site-packages\django\core\handlers\exception.py", line 55, in inner
    response = get_response(request)
  File "C:\Users\rben\AppData\Local\Programs\Python\Python310\lib\site-packages\django\core\handlers\base.py", line 197, in _get_response
    response = wrapped_callback(request, *callback_args, **callback_kwargs)
  File "C:\Users\rben\AppData\Local\Programs\Python\Python310\lib\site-packages\django\views\decorators\csrf.py", line 65, in _view_wrapper
    return view_func(request, *args, **kwargs)
  File "C:\Users\rben\AppData\Local\Programs\Python\Python310\lib\site-packages\django\views\decorators\http.py", line 64, in inner
    return func(request, *args, **kwargs)
  File "C:\Users\rben\Desktop\Nzungu\backend\api\decorators.py", line 79, in inner
    return func(request)
TypeError: getProducts() takes 0 positional arguments but 1 was given
INFO:django.utils.autoreload:C:\Users\rben\Desktop\Nzungu\backend\api\views.py changed, reloading.
INFO:django.utils.autoreload:C:\Users\rben\Desktop\Nzungu\backend\api\views.py changed, reloading.
INFO:django.utils.autoreload:C:\Users\rben\Desktop\Nzungu\backend\shared_models\models.py changed, reloading.
INFO:django.utils.autoreload:C:\Users\rben\Desktop\Nzungu\backend\api\views.py changed, reloading.
INFO:django.utils.autoreload:C:\Users\rben\Desktop\Nzungu\backend\api\views.py changed, reloading.
INFO:django.utils.autoreload:C:\Users\rben\Desktop\Nzungu\backend\api\views.py changed, reloading.
INFO:django.utils.autoreload:C:\Users\rben\Desktop\Nzungu\backend\shared_models\models.py changed, reloading.
INFO:django.utils.autoreload:C:\Users\rben\Desktop\Nzungu\backend\api\urls.py changed, reloading.
WARNING:django.request:Not Found: /api/get-filters
WARNING:django.request:Not Found: /api/get-product-filters
WARNING:django.request:Bad Request: /api/v1/get-categories
WARNING:django.request:Bad Request: /api/v1/get-categories
WARNING:django.request:Not Found: /
WARNING:django.request:Not Found: /api/v1/get-product-stock-filters
WARNING:django.request:Bad Request: /api/v1/get-products-stock-filters
WARNING:django.request:Forbidden: /api/v1/get-products-stock-filters
WARNING:django.request:Bad Request: /api/v1/get-categories
WARNING:django.request:Forbidden: /api/v1/get-categories
ERROR:django.request:Internal Server Error: /api/v1/get-products
Traceback (most recent call last):
  File "C:\Users\rben\AppData\Local\Programs\Python\Python310\lib\site-packages\django\db\backends\utils.py", line 105, in _execute
    return self.cursor.execute(sql, params)
  File "C:\Users\rben\AppData\Local\Programs\Python\Python310\lib\site-packages\django\db\backends\sqlite3\base.py", line 354, in execute
    return super().execute(query, params)
sqlite3.OperationalError: no such column: shared_models_productstockstatusfilter.last_updated

The above exception was the direct cause of the following exception:

Traceback (most recent call last):
  File "C:\Users\rben\AppData\Local\Programs\Python\Python310\lib\site-packages\django\core\handlers\exception.py", line 55, in inner
    response = get_response(request)
  File "C:\Users\rben\AppData\Local\Programs\Python\Python310\lib\site-packages\django\core\handlers\base.py", line 197, in _get_response
    response = wrapped_callback(request, *callback_args, **callback_kwargs)
  File "C:\Users\rben\AppData\Local\Programs\Python\Python310\lib\site-packages\django\views\decorators\csrf.py", line 65, in _view_wrapper
    return view_func(request, *args, **kwargs)
  File "C:\Users\rben\AppData\Local\Programs\Python\Python310\lib\site-packages\django\views\decorators\http.py", line 64, in inner
    return func(request, *args, **kwargs)
  File "C:\Users\rben\Desktop\Nzungu\backend\api\decorators.py", line 79, in inner
    return func(request)
  File "C:\Users\rben\Desktop\Nzungu\backend\api\views.py", line 178, in getProducts
    s_products = [product.toDict() for product in products]
  File "C:\Users\rben\AppData\Local\Programs\Python\Python310\lib\site-packages\django\db\models\query.py", line 400, in __iter__
    self._fetch_all()
  File "C:\Users\rben\AppData\Local\Programs\Python\Python310\lib\site-packages\django\db\models\query.py", line 1928, in _fetch_all
    self._result_cache = list(self._iterable_class(self))
  File "C:\Users\rben\AppData\Local\Programs\Python\Python310\lib\site-packages\django\db\models\query.py", line 91, in __iter__
    results = compiler.execute_sql(
  File "C:\Users\rben\AppData\Local\Programs\Python\Python310\lib\site-packages\django\db\models\sql\compiler.py", line 1574, in execute_sql
    cursor.execute(sql, params)
  File "C:\Users\rben\AppData\Local\Programs\Python\Python310\lib\site-packages\django\db\backends\utils.py", line 122, in execute
    return super().execute(sql, params)
  File "C:\Users\rben\AppData\Local\Programs\Python\Python310\lib\site-packages\django\db\backends\utils.py", line 79, in execute
    return self._execute_with_wrappers(
  File "C:\Users\rben\AppData\Local\Programs\Python\Python310\lib\site-packages\django\db\backends\utils.py", line 92, in _execute_with_wrappers
    return executor(sql, params, many, context)
  File "C:\Users\rben\AppData\Local\Programs\Python\Python310\lib\site-packages\django\db\backends\utils.py", line 100, in _execute
    with self.db.wrap_database_errors:
  File "C:\Users\rben\AppData\Local\Programs\Python\Python310\lib\site-packages\django\db\utils.py", line 91, in __exit__
    raise dj_exc_value.with_traceback(traceback) from exc_value
  File "C:\Users\rben\AppData\Local\Programs\Python\Python310\lib\site-packages\django\db\backends\utils.py", line 105, in _execute
    return self.cursor.execute(sql, params)
  File "C:\Users\rben\AppData\Local\Programs\Python\Python310\lib\site-packages\django\db\backends\sqlite3\base.py", line 354, in execute
    return super().execute(query, params)
django.db.utils.OperationalError: no such column: shared_models_productstockstatusfilter.last_updated
INFO:django.utils.autoreload:C:\Users\rben\Desktop\Nzungu\backend\api\views.py changed, reloading.
ERROR:django.request:Internal Server Error: /api/v1/upload
INFO:django.utils.autoreload:C:\Users\rben\Desktop\Nzungu\backend\api\decorators.py changed, reloading.
INFO:django.utils.autoreload:C:\Users\rben\Desktop\Nzungu\backend\api\views.py changed, reloading.
INFO:django.utils.autoreload:C:\Users\rben\Desktop\Nzungu\backend\api\decorators.py changed, reloading.
ERROR:django.request:Internal Server Error: /api/v1/upload
INFO:django.utils.autoreload:C:\Users\rben\Desktop\Nzungu\backend\api\decorators.py changed, reloading.
WARNING:django.request:Forbidden: /api/v1/upload
INFO:django.utils.autoreload:C:\Users\rben\Desktop\Nzungu\backend\shared_models\models.py changed, reloading.
INFO:django.utils.autoreload:C:\Users\rben\Desktop\Nzungu\backend\shared_models\models.py changed, reloading.
INFO:django.utils.autoreload:C:\Users\rben\Desktop\Nzungu\backend\shared_models\models.py changed, reloading.
INFO:django.utils.autoreload:C:\Users\rben\Desktop\Nzungu\backend\api\views.py changed, reloading.
INFO:django.utils.autoreload:C:\Users\rben\Desktop\Nzungu\backend\api\urls.py changed, reloading.
INFO:django.utils.autoreload:C:\Users\rben\Desktop\Nzungu\backend\api\urls.py changed, reloading.
WARNING:django.request:Method Not Allowed (GET): /api/v1/create-product
WARNING:django.request:Unsupported Media Type: /api/v1/create-product
WARNING:django.request:Bad Request: /api/v1/create-product
WARNING:django.request:Forbidden: /api/v1/create-product
WARNING:django.request:Forbidden: /api/v1/create-product
WARNING:django.request:Bad Request: /api/v1/create-product
WARNING:django.request:Method Not Allowed (OPTIONS): /api/v1/upload
INFO:django.utils.autoreload:C:\Users\rben\Desktop\Nzungu\backend\main\settings.py changed, reloading.
WARNING:django.request:Unauthorized: /api/v1/upload
WARNING:django.request:Unauthorized: /api/v1/upload
WARNING:django.request:Unauthorized: /api/v1/upload
WARNING:django.request:Bad Request: /api/v1/create-product
WARNING:django.request:Bad Request: /api/v1/create-product
WARNING:django.request:Bad Request: /api/v1/create-product
WARNING:django.request:Not Found: /api/v1/categories
WARNING:django.request:Bad Request: /api/v1/get-categories
WARNING:django.request:Bad Request: /api/v1/create-product
WARNING:django.request:Forbidden: /api/v1/upload
WARNING:django.request:Forbidden: /api/v1/create-product
WARNING:django.request:Forbidden: /api/v1/upload
WARNING:django.request:Bad Request: /api/v1/create-product
WARNING:django.request:Forbidden: /api/v1/upload
WARNING:django.request:Bad Request: /api/v1/create-product
WARNING:django.request:Forbidden: /api/v1/upload
WARNING:django.request:Bad Request: /api/v1/create-product
WARNING:django.request:Forbidden: /api/v1/upload
WARNING:django.request:Forbidden: /api/v1/upload
WARNING:django.request:Forbidden: /api/v1/create-product
WARNING:django.request:Forbidden: /api/v1/get-categories
WARNING:django.request:Forbidden: /api/v1/get-categories
WARNING:django.request:Bad Request: /api/v1/get-products
ERROR:django.request:Internal Server Error: /api/v1/get-products
Traceback (most recent call last):
  File "C:\Users\rben\AppData\Local\Programs\Python\Python310\lib\site-packages\django\core\handlers\exception.py", line 55, in inner
    response = get_response(request)
  File "C:\Users\rben\AppData\Local\Programs\Python\Python310\lib\site-packages\django\core\handlers\base.py", line 197, in _get_response
    response = wrapped_callback(request, *callback_args, **callback_kwargs)
  File "C:\Users\rben\AppData\Local\Programs\Python\Python310\lib\site-packages\django\views\decorators\csrf.py", line 65, in _view_wrapper
    return view_func(request, *args, **kwargs)
  File "C:\Users\rben\AppData\Local\Programs\Python\Python310\lib\site-packages\django\views\decorators\http.py", line 64, in inner
    return func(request, *args, **kwargs)
  File "C:\Users\rben\Desktop\Nzungu\backend\api\decorators.py", line 80, in inner
    return func(request)
  File "C:\Users\rben\Desktop\Nzungu\backend\api\views.py", line 179, in getProducts
    s_products = [product.toDict() for product in products]
  File "C:\Users\rben\AppData\Local\Programs\Python\Python310\lib\site-packages\django\db\models\query.py", line 400, in __iter__
    self._fetch_all()
  File "C:\Users\rben\AppData\Local\Programs\Python\Python310\lib\site-packages\django\db\models\query.py", line 1928, in _fetch_all
    self._result_cache = list(self._iterable_class(self))
  File "C:\Users\rben\AppData\Local\Programs\Python\Python310\lib\site-packages\django\db\models\query.py", line 91, in __iter__
    results = compiler.execute_sql(
  File "C:\Users\rben\AppData\Local\Programs\Python\Python310\lib\site-packages\django\db\models\sql\compiler.py", line 1561, in execute_sql
    sql, params = self.as_sql()
  File "C:\Users\rben\AppData\Local\Programs\Python\Python310\lib\site-packages\django\db\models\sql\compiler.py", line 747, in as_sql
    extra_select, order_by, group_by = self.pre_sql_setup(
  File "C:\Users\rben\AppData\Local\Programs\Python\Python310\lib\site-packages\django\db\models\sql\compiler.py", line 84, in pre_sql_setup
    self.setup_query(with_col_aliases=with_col_aliases)
  File "C:\Users\rben\AppData\Local\Programs\Python\Python310\lib\site-packages\django\db\models\sql\compiler.py", line 73, in setup_query
    self.select, self.klass_info, self.annotation_col_map = self.get_select(
  File "C:\Users\rben\AppData\Local\Programs\Python\Python310\lib\site-packages\django\db\models\sql\compiler.py", line 279, in get_select
    related_klass_infos = self.get_related_selections(select, select_mask)
  File "C:\Users\rben\AppData\Local\Programs\Python\Python310\lib\site-packages\django\db\models\sql\compiler.py", line 1379, in get_related_selections
    raise FieldError(
django.core.exceptions.FieldError: Invalid field name(s) given in select_related: 'product_stock_status_filter'. Choices are: referencedobject_ptr, category, image_uploaded
WARNING:django.request:Forbidden: /api/v1/get-categories
WARNING:django.request:Forbidden: /api/v1/get-products
WARNING:django.request:Forbidden: /api/v1/get-products
WARNING:django.request:Forbidden: /api/v1/get-categories
WARNING:django.request:Forbidden: /api/v1/get-categories
WARNING:django.request:Forbidden: /api/v1/get-products
WARNING:django.request:Forbidden: /api/v1/get-categories
WARNING:django.request:Forbidden: /api/v1/get-products
WARNING:django.request:Forbidden: /api/v1/get-products
WARNING:django.request:Forbidden: /api/v1/get-categories
ERROR:django.request:Internal Server Error: /api/v1/get-products
Traceback (most recent call last):
  File "C:\Users\rben\AppData\Local\Programs\Python\Python310\lib\site-packages\django\core\handlers\exception.py", line 55, in inner
    response = get_response(request)
  File "C:\Users\rben\AppData\Local\Programs\Python\Python310\lib\site-packages\django\core\handlers\base.py", line 197, in _get_response
    response = wrapped_callback(request, *callback_args, **callback_kwargs)
  File "C:\Users\rben\AppData\Local\Programs\Python\Python310\lib\site-packages\django\views\decorators\csrf.py", line 65, in _view_wrapper
    return view_func(request, *args, **kwargs)
  File "C:\Users\rben\AppData\Local\Programs\Python\Python310\lib\site-packages\django\views\decorators\http.py", line 64, in inner
    return func(request, *args, **kwargs)
  File "C:\Users\rben\Desktop\Nzungu\backend\api\decorators.py", line 30, in inner
    item = dynamo_db.get_item(
  File "C:\Users\rben\AppData\Local\Programs\Python\Python310\lib\site-packages\botocore\client.py", line 601, in _api_call
    return self._make_api_call(operation_name, kwargs)
  File "C:\Users\rben\AppData\Local\Programs\Python\Python310\lib\site-packages\botocore\context.py", line 123, in wrapper
    return func(*args, **kwargs)
  File "C:\Users\rben\AppData\Local\Programs\Python\Python310\lib\site-packages\botocore\client.py", line 1074, in _make_api_call
    raise error_class(parsed_response, operation_name)
botocore.exceptions.ClientError: An error occurred (UnrecognizedClientException) when calling the GetItem operation: The security token included in the request is invalid.
ERROR:django.request:Internal Server Error: /api/v1/get-categories
Traceback (most recent call last):
  File "C:\Users\rben\AppData\Local\Programs\Python\Python310\lib\site-packages\django\core\handlers\exception.py", line 55, in inner
    response = get_response(request)
  File "C:\Users\rben\AppData\Local\Programs\Python\Python310\lib\site-packages\django\core\handlers\base.py", line 197, in _get_response
    response = wrapped_callback(request, *callback_args, **callback_kwargs)
  File "C:\Users\rben\AppData\Local\Programs\Python\Python310\lib\site-packages\django\views\decorators\csrf.py", line 65, in _view_wrapper
    return view_func(request, *args, **kwargs)
  File "C:\Users\rben\AppData\Local\Programs\Python\Python310\lib\site-packages\django\views\decorators\http.py", line 64, in inner
    return func(request, *args, **kwargs)
  File "C:\Users\rben\Desktop\Nzungu\backend\api\decorators.py", line 30, in inner
    item = dynamo_db.get_item(
  File "C:\Users\rben\AppData\Local\Programs\Python\Python310\lib\site-packages\botocore\client.py", line 601, in _api_call
    return self._make_api_call(operation_name, kwargs)
  File "C:\Users\rben\AppData\Local\Programs\Python\Python310\lib\site-packages\botocore\context.py", line 123, in wrapper
    return func(*args, **kwargs)
  File "C:\Users\rben\AppData\Local\Programs\Python\Python310\lib\site-packages\botocore\client.py", line 1074, in _make_api_call
    raise error_class(parsed_response, operation_name)
botocore.exceptions.ClientError: An error occurred (UnrecognizedClientException) when calling the GetItem operation: The security token included in the request is invalid.
ERROR:django.request:Internal Server Error: /api/v1/get-categories
Traceback (most recent call last):
  File "C:\Users\rben\AppData\Local\Programs\Python\Python310\lib\site-packages\django\core\handlers\exception.py", line 55, in inner
    response = get_response(request)
  File "C:\Users\rben\AppData\Local\Programs\Python\Python310\lib\site-packages\django\core\handlers\base.py", line 197, in _get_response
    response = wrapped_callback(request, *callback_args, **callback_kwargs)
  File "C:\Users\rben\AppData\Local\Programs\Python\Python310\lib\site-packages\django\views\decorators\csrf.py", line 65, in _view_wrapper
    return view_func(request, *args, **kwargs)
  File "C:\Users\rben\AppData\Local\Programs\Python\Python310\lib\site-packages\django\views\decorators\http.py", line 64, in inner
    return func(request, *args, **kwargs)
  File "C:\Users\rben\Desktop\Nzungu\backend\api\decorators.py", line 30, in inner
    item = dynamo_db.get_item(
  File "C:\Users\rben\AppData\Local\Programs\Python\Python310\lib\site-packages\botocore\client.py", line 601, in _api_call
    return self._make_api_call(operation_name, kwargs)
  File "C:\Users\rben\AppData\Local\Programs\Python\Python310\lib\site-packages\botocore\context.py", line 123, in wrapper
    return func(*args, **kwargs)
  File "C:\Users\rben\AppData\Local\Programs\Python\Python310\lib\site-packages\botocore\client.py", line 1074, in _make_api_call
    raise error_class(parsed_response, operation_name)
botocore.exceptions.ClientError: An error occurred (UnrecognizedClientException) when calling the GetItem operation: The security token included in the request is invalid.
ERROR:django.request:Internal Server Error: /api/v1/get-products
Traceback (most recent call last):
  File "C:\Users\rben\AppData\Local\Programs\Python\Python310\lib\site-packages\django\core\handlers\exception.py", line 55, in inner
    response = get_response(request)
  File "C:\Users\rben\AppData\Local\Programs\Python\Python310\lib\site-packages\django\core\handlers\base.py", line 197, in _get_response
    response = wrapped_callback(request, *callback_args, **callback_kwargs)
  File "C:\Users\rben\AppData\Local\Programs\Python\Python310\lib\site-packages\django\views\decorators\csrf.py", line 65, in _view_wrapper
    return view_func(request, *args, **kwargs)
  File "C:\Users\rben\AppData\Local\Programs\Python\Python310\lib\site-packages\django\views\decorators\http.py", line 64, in inner
    return func(request, *args, **kwargs)
  File "C:\Users\rben\Desktop\Nzungu\backend\api\decorators.py", line 30, in inner
    item = dynamo_db.get_item(
  File "C:\Users\rben\AppData\Local\Programs\Python\Python310\lib\site-packages\botocore\client.py", line 601, in _api_call
    return self._make_api_call(operation_name, kwargs)
  File "C:\Users\rben\AppData\Local\Programs\Python\Python310\lib\site-packages\botocore\context.py", line 123, in wrapper
    return func(*args, **kwargs)
  File "C:\Users\rben\AppData\Local\Programs\Python\Python310\lib\site-packages\botocore\client.py", line 1074, in _make_api_call
    raise error_class(parsed_response, operation_name)
botocore.exceptions.ClientError: An error occurred (UnrecognizedClientException) when calling the GetItem operation: The security token included in the request is invalid.
ERROR:django.request:Internal Server Error: /api/v1/get-products
Traceback (most recent call last):
  File "C:\Users\rben\AppData\Local\Programs\Python\Python310\lib\site-packages\django\core\handlers\exception.py", line 55, in inner
    response = get_response(request)
  File "C:\Users\rben\AppData\Local\Programs\Python\Python310\lib\site-packages\django\core\handlers\base.py", line 197, in _get_response
    response = wrapped_callback(request, *callback_args, **callback_kwargs)
  File "C:\Users\rben\AppData\Local\Programs\Python\Python310\lib\site-packages\django\views\decorators\csrf.py", line 65, in _view_wrapper
    return view_func(request, *args, **kwargs)
  File "C:\Users\rben\AppData\Local\Programs\Python\Python310\lib\site-packages\django\views\decorators\http.py", line 64, in inner
    return func(request, *args, **kwargs)
  File "C:\Users\rben\Desktop\Nzungu\backend\api\decorators.py", line 30, in inner
    item = dynamo_db.get_item(
  File "C:\Users\rben\AppData\Local\Programs\Python\Python310\lib\site-packages\botocore\client.py", line 601, in _api_call
    return self._make_api_call(operation_name, kwargs)
  File "C:\Users\rben\AppData\Local\Programs\Python\Python310\lib\site-packages\botocore\context.py", line 123, in wrapper
    return func(*args, **kwargs)
  File "C:\Users\rben\AppData\Local\Programs\Python\Python310\lib\site-packages\botocore\client.py", line 1074, in _make_api_call
    raise error_class(parsed_response, operation_name)
botocore.errorfactory.ResourceNotFoundException: An error occurred (ResourceNotFoundException) when calling the GetItem operation: Requested resource not found
ERROR:django.request:Internal Server Error: /api/v1/get-categories
Traceback (most recent call last):
  File "C:\Users\rben\AppData\Local\Programs\Python\Python310\lib\site-packages\django\core\handlers\exception.py", line 55, in inner
    response = get_response(request)
  File "C:\Users\rben\AppData\Local\Programs\Python\Python310\lib\site-packages\django\core\handlers\base.py", line 197, in _get_response
    response = wrapped_callback(request, *callback_args, **callback_kwargs)
  File "C:\Users\rben\AppData\Local\Programs\Python\Python310\lib\site-packages\django\views\decorators\csrf.py", line 65, in _view_wrapper
    return view_func(request, *args, **kwargs)
  File "C:\Users\rben\AppData\Local\Programs\Python\Python310\lib\site-packages\django\views\decorators\http.py", line 64, in inner
    return func(request, *args, **kwargs)
  File "C:\Users\rben\Desktop\Nzungu\backend\api\decorators.py", line 30, in inner
    item = dynamo_db.get_item(
  File "C:\Users\rben\AppData\Local\Programs\Python\Python310\lib\site-packages\botocore\client.py", line 601, in _api_call
    return self._make_api_call(operation_name, kwargs)
  File "C:\Users\rben\AppData\Local\Programs\Python\Python310\lib\site-packages\botocore\context.py", line 123, in wrapper
    return func(*args, **kwargs)
  File "C:\Users\rben\AppData\Local\Programs\Python\Python310\lib\site-packages\botocore\client.py", line 1074, in _make_api_call
    raise error_class(parsed_response, operation_name)
botocore.errorfactory.ResourceNotFoundException: An error occurred (ResourceNotFoundException) when calling the GetItem operation: Requested resource not found
